<?xml version="1.0"?>
<robot name="elbow_exoskeleton">


  <material name="Blue">
      <color rgba="0.0 0.0 0.8 1.0"/>
  </material>
  <material name="Green">
      <color rgba="0.0 0.8 0.0 1.0"/>
  </material>
  <material name="Red">
      <color rgba="0.8 0.0 0.0 1.0"/>
  </material>
  <!--************************-->
  <!--        SHOULDER        -->
  <!--************************-->

  <link name="shoulder_link_1">
    <inertial>
        <origin rpy="0 0 0" xyz="0 0 0"/>
        <mass value="0.1"/>
        <inertia ixx="0.0168" ixy="0.0" ixz="0.0" iyy="0.0168" iyz="0.0" izz="0.0168"/>
    </inertial>
    <visual>
        <origin rpy="0 0 0" xyz="0 0 0"/>
        <geometry>
            <cylinder length="0" radius="0"/>
        </geometry>
        <material name="Blue"/>
    </visual>
    <collision>
        <origin rpy="0 0 0" xyz="0 0 0"/>
        <geometry>
            <cylinder length="0" radius="0"/>
        </geometry>
    </collision>
  </link>

  <link name="shoulder_link_2">
    <inertial>
        <origin xyz="0 0 0" rpy="0 0 0" />
        <mass value="0.1"/>
        <inertia ixx="0.0168" ixy="0.0" ixz="0.0" iyy="0.0168" iyz="0.0" izz="0.0168"/>
    </inertial>
    <visual>
        <origin rpy="0 0 0" xyz="0 0 0"/>
        <geometry>
            <cylinder length="0" radius="0"/>
        </geometry>
        <material name="Blue"/>
    </visual>
    <collision>
        <origin rpy="0 0 0" xyz="0 0 0"/>
        <geometry>
            <cylinder length="0" radius="0"/>
        </geometry>
    </collision>
  </link>

  <link name="shoulder_link_3">
    <inertial>
        <origin xyz="0 0 0" rpy="0 0 0" />
        <mass value="0.1"/>
        <inertia ixx="0.0168" ixy="0.0" ixz="0.0" iyy="0.0168" iyz="0.0" izz="0.0168"/>
    </inertial>
    <visual>
        <origin rpy="0 0 0" xyz="0 0 0"/>
        <geometry>
            <cylinder length="0" radius="0"/>
        </geometry>
        <material name="Blue"/>
    </visual>
    <collision>
        <origin rpy="0 0 0" xyz="0 0 0"/>
        <geometry>
            <cylinder length="0" radius="0"/>
        </geometry>
    </collision>
  </link>

  <link name="upper_arm">
    <inertial>
      <origin rpy="1.57 0 1.57" xyz="0.06 0.3 -2.08"/>
      <mass value="2.24"/> <!--2.24-->
      <inertia ixx="0.0168" ixy="0.0" ixz="0.0" iyy="0.0168" iyz="0.0" izz="0.0168"/>
    </inertial>
    <visual>
      <geometry>
        <mesh filename="package://arm.obj" scale="1.3 1.51 1.3"/>
      </geometry>
      <material name="dark_green">
        <color rgba="0.2 0.5 0.2 1"/>
      </material>
      <origin rpy="1.57 0 1.57" xyz="0.06 0.3 -2.08"/>
    </visual>
    <collision>
      <origin rpy="1.57 0 1.57" xyz="0.06 0.3 -2.08"/>
      <geometry>
        <mesh filename="package://arm.obj" scale="1. 1. 1."/>
      </geometry>
    </collision>
  </link>



  <joint name="shoulder_joint_x" type="revolute">
    <origin xyz="0 0 0" rpy="0 0 0"/>
    <parent link="shoulder_link_1"/>
    <child link="shoulder_link_2"/>
    <dynamics damping="1.0" friction="1.0"/>
    <limit effort="100" lower="-3.14159" upper="1.5708" velocity="50"/>
    <axis xyz="1 0 0" />
  </joint>

  <joint name="shoulder_joint_y" type="revolute">
    <origin xyz="0 0 0" rpy="0 0 0"/>
    <parent link="shoulder_link_2"/>
    <child link="shoulder_link_3"/>
    <dynamics damping="1.0" friction="1.0"/>
    <limit effort="100" lower="-3.14159" upper="1.5708" velocity="50"/>
    <axis xyz="0 1 0" />
  </joint>

  <joint name="shoulder_joint_z" type="revolute">
    <origin xyz="0 0 0" rpy="0 0 0"/>
    <parent link="shoulder_link_3"/>
    <child link="upper_arm"/>
    <dynamics damping="1.0" friction="1.0"/>
    <limit effort="100" lower="-3.14159" upper="3.14159" velocity="50"/>
    <axis xyz="0 0 1" />
  </joint>


  <!--************************-->
  <!--         ELBOW          -->
  <!--************************-->

  <link name="fore_arm">
    <inertial>
      <origin rpy="1.57 0 1.57" xyz="0.075 0.3 -1.34"/>
      <mass value="1.309"/> <!--1.309-->
      <inertia ixx="0.027270833" ixy="0.0" ixz="0.0" iyy="0.027270833" iyz="0.0" izz="0.027270833"/>
     </inertial>
    <visual>
      <geometry>
        <mesh filename="package://forearm.obj" scale="1.3 1.2 1.3"/>
      </geometry>
      <material name="green">
        <color rgba="0 1 0 1"/>
      </material>
      <origin rpy="1.57 0 1.57" xyz="0.075 0.3 -1.34"/>
    </visual>
    <collision>
      <origin rpy="1.57 0 1.57" xyz="0.075 0.3 -1.34"/>
      <geometry>
        <mesh filename="package://forearm.obj" scale="1 1 1"/>
      </geometry>
    </collision>
  </link>


  <joint name="elbow" type="revolute">
    <origin xyz="0 0 -0.35" rpy="0 0 0"/>
    <parent link="upper_arm"/>
    <child link="fore_arm"/>
    <dynamics damping="1.0" friction="1.0"/>
    <limit effort="100" lower="-3.14159" upper="0" velocity="50"/>
    <axis xyz="0 1 0" />
  </joint>


  <!--************************-->
  <!--         WRIST          -->
  <!--************************-->

  <link name="hand">
    <inertial>
      <mass value="0.455"/>
      <origin rpy="1.57 0 1.57" xyz="0 0 0"/>
      <inertia ixx="0.004794614" iyy="0.004794614" izz="0.004794614" ixy="0.0" ixz="0.0" iyz="0.0"/>
    </inertial>
    <visual>
      <geometry>
        <mesh filename="package://hand.obj" scale="1 1 1"/>
      </geometry>
      <material name="brown">
        <color rgba="0.5 0.2 0.2 1"/>
      </material>
      <origin rpy="1.57 0 1.57" xyz="0.06 0.27 -0.85"/>
    </visual>
    <collision>
      <origin rpy="1.57 0 1.57" xyz="0 0 0"/>
      <geometry>
        <mesh filename="package://hand.obj" scale="1 1 1"/>
      </geometry>
    </collision>
  </link>


  <joint name="wrist" type="revolute">
    <origin xyz="0 -0.05 -0.35" rpy="0 0 0"/>
    <parent link="fore_arm"/>
    <child link="hand"/>
    <limit effort="0" lower="-0.001" upper="0.001" velocity="1"/>
    <axis xyz="0 0 1" />
  </joint>

</robot>